Workbook

Sheet PROGRESSION
A1: GELARAN MAJU SDN BHD | R1: #VALUE!
A2: PROJECT: THE CAPITOL / MSK
A3: Report Date: 29 AUGUST 2026
A4: LEVEL | C4: COLD WATER | G4: =(C46+D46+E46+F46+G46+H46+I46)/7 -> 0.44053571 | J4: SANITARY | L4: =(J46+K46+L46+M46+N46)/5 -> 0.3365 | O4: IRRIGATION | Q4: =(O46+P46+Q46+R46)/4 -> 0.08
C5: PIPE SLEEVE | D5: PUMP | E5: PUMP CONTROL PANEL | F5: TRANSFER PUMP PIPES | G5: L31 & 31M ROOF PIPING | H5: CW TENANT | I5: BACKSHAFT CW & FW TOILETS | J5: HOSEREEL FLOORTRAP & STACK | K5: SANITARY TENANT | L5: TOILET PIPE DISTRIBUTION & HACKING | M5: SANITARY TOILETS | N5: SANITARY WARES INSTALLATION | O5: IRRIGATION OUTLET | P5: IRRIGATION INLET | Q5: IRRIGATION WIRING | R5: IRRIGATION CONTROL PANEL
A6: 13 | B6: TOWER A | C6: 1 | D6: N/A | E6: N/A | F6: 1 | G6: N/A | H6: 0 | I6: 0 | J6: =0/6 -> 0 | K6: 0 | L6: =0/4 -> 0 | M6: =0/4 -> 0 | N6: 0 | O6: 1 | P6: 0.9 | Q6: 0 | R6: N/A
A7: 14 | C7: 1 | F7: 1 | H7: 0.9 | I7: 1 | J7: =6/6 -> 1 | K7: 1 | L7: =4/4 -> 1 | M7: =4/4 -> 1 | N7: 1 | O7: 1 | P7: 0 | Q7: 0
A8: 15 | C8: 1 | F8: 1 | H8: 0.9 | I8: 1 | J8: =6/6 -> 1 | K8: 1 | L8: =4/4 -> 1 | M8: =4/4 -> 1 | N8: 1 | O8: 1 | P8: 0 | Q8: 0
A9: 16 | C9: 1 | F9: 1 | H9: 0.9 | I9: 0.1 | J9: =6/6 -> 1 | K9: 1 | L9: =4/4 -> 1 | M9: =4/4 -> 1 | N9: 0.5 | O9: 1 | P9: 0 | Q9: 0
A10: 17 | C10: 1 | F10: 1 | H10: 0.9 | I10: 0 | J10: =6/6 -> 1 | K10: 1 | L10: =4/4 -> 1 | M10: =4/4 -> 1 | N10: 0 | O10: 1 | P10: 0 | Q10: 0
A11: 18 | C11: 1 | F11: 1 | H11: 0.9 | I11: 0 | J11: =6/6 -> 1 | K11: 1 | L11: =4/4 -> 1 | M11: =4/4 -> 1 | N11: 0 | O11: 0.5 | P11: 0 | Q11: 0
A12: 19 | C12: 1 | F12: 1 | H12: 0.9 | I12: 0 | J12: =6/6 -> 1 | K12: 1 | L12: =4/4 -> 1 | M12: =4/4 -> 1 | N12: 0 | O12: 0 | P12: 0 | Q12: 0
A13: 20 | C13: 1 | F13: 1 | H13: 0.9 | I13: 0 | J13: =6/6 -> 1 | K13: 0.5 | L13: =0/4 -> 0 | M13: =4/4 -> 1 | N13: 0 | O13: 0 | P13: 0 | Q13: 0
A14: 21 | C14: 1 | F14: 1 | H14: 0.9 | I14: 0 | J14: =0.6/6 -> 0.1 | K14: 0 | L14: =0/4 -> 0 | M14: =4/4 -> 1 | N14: 0 | O14: 0 | P14: 0 | Q14: 0
A15: 22 | C15: 1 | F15: 0 | H15: 0.9 | I15: 0 | J15: =0/6 -> 0 | K15: 0 | L15: =4/4 -> 1 | M15: =4/4 -> 1 | N15: 0 | O15: 0 | P15: 0 | Q15: 0 | R15: 0
A16: 23 | C16: 1 | F16: 0 | H16: 0.9 | I16: 0 | J16: =0/6 -> 0 | K16: 0 | L16: =0/4 -> 0 | M16: =0/4 -> 0 | N16: 0 | O16: 0 | P16: 0 | Q16: 0 | R16: N/A
A17: 24 | C17: 1 | F17: 0 | H17: 0.9 | I17: 0 | J17: =0/6 -> 0 | K17: 0 | L17: =0/4 -> 0 | M17: =0/4 -> 0 | N17: 0 | O17: 0 | P17: 0 | Q17: 0
A18: 25 | C18: 1 | F18: 0 | H18: 0.9 | I18: 0 | J18: =0/6 -> 0 | K18: 0 | L18: =0/4 -> 0 | M18: =4/4 -> 1 | N18: 0 | O18: 0 | P18: 0 | Q18: 0
A19: 26 | C19: 1 | F19: 0 | H19: 0.9 | I19: 0 | J19: =0/6 -> 0 | K19: 0 | L19: =3.2/4 -> 0.8 | M19: =0/4 -> 0 | N19: 0 | O19: 0 | P19: 0 | Q19: 0
A20: 27 | C20: 1 | F20: 0 | H20: 0.9 | I20: 0 | J20: =0/6 -> 0 | K20: 0 | L20: =0/4 -> 0 | M20: =4/4 -> 1 | N20: 0 | O20: 0 | P20: 0 | Q20: 0
A21: 28 | C21: 1 | F21: 0 | H21: 0.9 | I21: 0 | J21: =0/6 -> 0 | K21: 0 | L21: =0/4 -> 0 | M21: =0/4 -> 0 | N21: 0 | O21: 0 | P21: 0 | Q21: 0
A22: 29 | C22: 1 | F22: 0 | H22: 0.9 | I22: 0 | J22: =0/6 -> 0 | K22: 0 | L22: =0/4 -> 0 | M22: =0/4 -> 0 | N22: 0 | O22: 0 | P22: 0 | Q22: 0
A23: 30 | C23: 1 | F23: 0 | H23: 0 | I23: 0 | J23: =0/6 -> 0 | K23: 0 | L23: =0/4 -> 0 | M23: =0/4 -> 0 | N23: 0 | O23: 0 | P23: 0 | Q23: 0
A24: 31 | C24: 0.55 | D24: 0.9 | E24: 0.9 | F24: 0 | G24: 0 | H24: 0 | I24: 0 | J24: =0/6 -> 0 | K24: 0 | L24: =0/4 -> 0 | M24: =0/4 -> 0 | N24: 0 | O24: 0 | P24: 0 | Q24: 0
A25: 31M | C25: 0.1 | D25: 0 | E25: 0 | F25: 0 | G25: 0 | H25: 0 | I25: 0 | J25: =0/6 -> 0 | K25: 0 | L25: =0/4 -> 0 | M25: =0/4 -> 0 | N25: 0 | O25: 0 | P25: 0 | Q25: 0 | R25: 0
A26: 13 | B26: TOWER B | C26: 1 | D26: N/A | E26: N/A | F26: 1 | G26: N/A | H26: 0 | I26: 0 | J26: =0.6/6 -> 0.1 | K26: 0 | L26: =0/4 -> 0 | M26: =0/4 -> 0 | N26: 0 | O26: 1 | P26: 0.9 | Q26: 0 | R26: N/A
A27: 14 | C27: 1 | F27: 1 | H27: 0.9 | I27: 1 | J27: =6/6 -> 1 | K27: 1 | L27: =4/4 -> 1 | M27: =4/4 -> 1 | N27: 1 | O27: 1 | P27: 0 | Q27: 0
A28: 15 | C28: 1 | F28: 1 | H28: 0.9 | I28: 1 | J28: =6/6 -> 1 | K28: 1 | L28: =4/4 -> 1 | M28: =4/4 -> 1 | N28: 1 | O28: 1 | P28: 0 | Q28: 0
A29: 16 | C29: 1 | F29: 1 | H29: 0.9 | I29: 0.1 | J29: =6/6 -> 1 | K29: 1 | L29: =4/4 -> 1 | M29: =4/4 -> 1 | N29: 0 | O29: 1 | P29: 0 | Q29: 0
A30: 17 | C30: 1 | F30: 1 | H30: 0.9 | I30: 0 | J30: =6/6 -> 1 | K30: 1 | L30: =4/4 -> 1 | M30: =4/4 -> 1 | N30: 0 | O30: 1 | P30: 0 | Q30: 0
A31: 18 | C31: 1 | F31: 1 | H31: 0.9 | I31: 0 | J31: =6/6 -> 1 | K31: 1 | L31: =4/4 -> 1 | M31: =4/4 -> 1 | N31: 0 | O31: 0.5 | P31: 0 | Q31: 0
A32: 19 | C32: 1 | F32: 1 | H32: 0.9 | I32: 0 | J32: =6/6 -> 1 | K32: 1 | L32: =4/4 -> 1 | M32: =4/4 -> 1 | N32: 0 | O32: 0 | P32: 0 | Q32: 0
A33: 20 | C33: 1 | F33: 1 | H33: 0.9 | I33: 0 | J33: =6/6 -> 1 | K33: 0.5 | L33: =0/4 -> 0 | M33: =4/4 -> 1 | N33: 0 | O33: 0 | P33: 0 | Q33: 0
A34: 21 | C34: 1 | F34: 1 | H34: 0.9 | I34: 0 | J34: =0/6 -> 0 | K34: 0 | L34: =0/4 -> 0 | M34: =4/4 -> 1 | N34: 0 | O34: 0 | P34: 0 | Q34: 0
A35: 22 | C35: 1 | F35: 0 | H35: 0.9 | I35: 0 | J35: =0/6 -> 0 | K35: 0 | L35: =4/4 -> 1 | M35: =4/4 -> 1 | N35: 0 | O35: 0 | P35: 0 | Q35: 0 | R35: 0
A36: 23 | C36: 1 | F36: 0 | H36: 0.9 | I36: 0 | J36: =0/6 -> 0 | K36: 0 | L36: =0/4 -> 0 | M36: =0/4 -> 0 | N36: 0 | O36: 0 | P36: 0 | Q36: 0 | R36: N/A
A37: 24 | C37: 1 | F37: 0 | H37: 0.9 | I37: 0 | J37: =0/6 -> 0 | K37: 0 | L37: =0/4 -> 0 | M37: =0/4 -> 0 | N37: 0 | O37: 0 | P37: 0 | Q37: 0
A38: 25 | C38: 1 | F38: 0 | H38: 0.9 | I38: 0 | J38: =0/6 -> 0 | K38: 0 | L38: =0/4 -> 0 | M38: =0/4 -> 0 | N38: 0 | O38: 0 | P38: 0 | Q38: 0
A39: 26 | C39: 1 | F39: 0 | H39: 0.9 | I39: 0 | J39: =0/6 -> 0 | K39: 0 | L39: =3.2/4 -> 0.8 | M39: =0/4 -> 0 | N39: 0 | O39: 0 | P39: 0 | Q39: 0
A40: 27 | C40: 1 | F40: 0 | H40: 0.9 | I40: 0 | J40: =0/6 -> 0 | K40: 0 | L40: =0/4 -> 0 | M40: =0/4 -> 0 | N40: 0 | O40: 0 | P40: 0 | Q40: 0
...

Sheet Sheet1
B1: GELARAN MAJU SDN BHD | F1: #VALUE!
B2: PROJECT: THE CAPITOL / MSK
B3: =PROGRESSION!A3 -> Report Date: 29 AUGUST 2026
B4: SCOPE | D4: TEAM | E4: PROGRESS % | F4: STATUS | H4: SUPAHAM | I4: LEADER | J4: ASSISTANT
B5: COLD WATER | C5: PIPE SLEEVE | D5: suhairi | E5: =PROGRESSION!C46 -> 0.93125 | F5: =IF(E5>=1,"Complete",IF(E5=0,"Not Started","In Progress")) -> In Progress | H5: team 1 | I5: SOLIHIN | J5: ASHRAFUL | K5: JIARUL | L5: YASIN
C6: PUMP | D6: n/a | E6: =PROGRESSION!D46 -> 0.45 | F6: =IF(E6>=1,"Complete",IF(E6=0,"Not Started","In Progress")) -> In Progress | H6: team 2 | I6: ASGAR | J6: RANA
C7: PUMP CONTROL PANEL | E7: =PROGRESSION!E46 -> 0.45 | F7: =IF(E7>=1,"Complete",IF(E7=0,"Not Started","In Progress")) -> In Progress | H7: team 3 | I7: SUHAIRI | J7: SUPENDI
C8: TRANSFER PUMP PIPES | D8: subs-aryan | E8: =PROGRESSION!F46 -> 0.45 | F8: =IF(E8>=1,"Complete",IF(E8=0,"Not Started","In Progress")) -> In Progress | H8: team 4 | I8: BILAL | J8: FARHAD | K8: SOFIKUL | L8: SYAHIB | M8: AMIRUL | N8: NURUL | O8: NAZMUL
C9: L31 & 31M ROOF PIPING | E9: =PROGRESSION!G46 -> 0 | F9: =IF(E9>=1,"Complete",IF(E9=0,"Not Started","In Progress")) -> Not Started | H9: team 5 | I9: JUWEL | J9: BADOL
C10: CW TENANT | D10: asgar | E10: =PROGRESSION!H46 -> 0.6975 | F10: =IF(E10>=1,"Complete",IF(E10=0,"Not Started","In Progress")) -> In Progress | H10: team 6 | I10: JILLUR | J10: ISLAM
C11: BACKSHAFT CW & FW TOILETS | D11: jillur/sarip | E11: =PROGRESSION!I46 -> 0.105 | F11: =IF(E11>=1,"Complete",IF(E11=0,"Not Started","In Progress")) -> In Progress | H11: team 7 | I11: SARIP | J11: SYAHIB
B12: SANITARY | C12: HOSEREEL FLOORTRAP & STACK | D12: emon | E12: =PROGRESSION!J46 -> 0.355 | F12: =IF(E12>=1,"Complete",IF(E12=0,"Not Started","In Progress")) -> In Progress | H12: team 8 | I12: EMON | J12: MAHMUD
C13: SANITARY TENANT | E13: =PROGRESSION!K46 -> 0.325 | F13: =IF(E13>=1,"Complete",IF(E13=0,"Not Started","In Progress")) -> In Progress | H13: team 9 | I13: IBNU | J13: DAMIL
C14: TOILET PIPE DISTRIBUTION & HACKING | D14: bilal | E14: =PROGRESSION!L46 -> 0.39 | F14: =IF(E14>=1,"Complete",IF(E14=0,"Not Started","In Progress")) -> In Progress | H14: team 10 | I14: KAMAL
C15: SANITARY TOILETS TOWER A | D15: subs-aipoon | E15: =AVERAGE(PROGRESSION!M6:M25) -> 0.55 | F15: =IF(E15>=1,"Complete",IF(E15=0,"Not Started","In Progress")) -> In Progress
C16: SANITARY TOILETS TOWER B | E16: =AVERAGE(PROGRESSION!M26:M45) -> 0.45 | F16: =IF(E16>=1,"Complete",IF(E16=0,"Not Started","In Progress")) -> In Progress
C17: SANITARY WARES INSTALLATION | D17: jiarul | E17: =PROGRESSION!N46 -> 0.1125 | F17: =IF(E17>=1,"Complete",IF(E17=0,"Not Started","In Progress")) -> In Progress
B18: IRRIGATION | C18: IRRIGATION OUTLET | D18: juwel | E18: =PROGRESSION!O46 -> 0.275 | F18: =IF(E18>=1,"Complete",IF(E18=0,"Not Started","In Progress")) -> In Progress
C19: IRRIGATION INLET | E19: =PROGRESSION!P46 -> 0.045 | F19: =IF(E19>=1,"Complete",IF(E19=0,"Not Started","In Progress")) -> In Progress
C20: IRRIGATION WIRING | E20: =PROGRESSION!Q46 -> 0 | F20: =IF(E20>=1,"Complete",IF(E20=0,"Not Started","In Progress")) -> Not Started
C21: IRRIGATION CONTROL PANEL | E21: =PROGRESSION!R46 -> 0 | F21: =IF(E21>=1,"Complete",IF(E21=0,"Not Started","In Progress")) -> Not Started

Sheet Sheet2
B2: GM | E2: SUBS
B3: 1 | C3: SUPAHAM | D3: 2000 | E3: 1 | F3: AIPOON | G3: 0
B4: 2 | C4: SOLIHIN | D4: 1000 | E4: 2 | F4: WELDER
B5: 3 | C5: ASGAR | D5: 500
B6: 4 | C6: SUHAIRI | D6: 700
B7: 5 | C7: BILAL | D7: 500
B8: 6 | C8: JUWEL | D8: 500
B9: 7 | C9: JILLUR | D9: 500
B10: 8 | C10: SARIP | D10: 700
B11: 9 | C11: EMON | D11: 500
B12: 10 | C12: IBNU | D12: 500
B13: 11 | C13: KAMAL | D13: 500
B14: 12 | C14: YASIN | D14: 500
B15: 13 | C15: SOFIKUL | D15: 1000
B16: 14 | C16: NAZMUL | D16: 500
... B18: 16 | C18: NURUL | D18: 500
B19: 17 | C19: JIARUL | D19: n/a
B20: 18 | C20: SUPENDI | D20: 500
B21: 19 | C21: RANA | D21: 500
B22: 20 | C22: ASHRAFUL | D22: 500
B23: 21 | C23: FARHAD | D23: 500
B24: 22 | C24: BADOL | D24: 500
B25: 23 | C25: ISLAM | D25: 500
B26: 24 | C26: SYAHIB | D26: 500
B27: 25 | C27: AMIRUL | D27: 500
B28: 26 | C28: DAMIL | D28: 500
B29: 27 | C29: KAMAL | D29: 500
C30: TOTAL | D30: =SUM(D3:D29) -> 15900

Sheet COMPARE
A1: Tower A vs Tower B | % complete
A2: =IF(C8=D8,"Overall tied",IF(C8>D8,"Tower A leads overall by "&TEXT(C8-D8,"0.0%"),"Tower B leads overall by "&TEXT(D8-C8,"0.0%"))) -> Tower A leads overall by 1.1%
A4: PACKAGE | C4: Tower A | D4: Tower B | E4: Gap (A−B) | F4: Leader
A5: COLD WATER | C5: =AVERAGE(C11:C17) -> 0.44392857 | D5: =AVERAGE(D11:D17) -> 0.43714286 | E5: =C5-D5 -> 0.0067857143 | F5: =IF(C5=D5,"Tie",IF(C5>D5,"Tower A","Tower B")) -> Tower A
A6: SANITARY | C6: =AVERAGE(C18:C22) -> 0.349 | D6: =AVERAGE(D18:D22) -> 0.324 | E6: =C6-D6 -> 0.025 | F6: =IF(C6=D6,"Tie",IF(C6>D6,"Tower A","Tower B")) -> Tower A
A7: IRRIGATION | C7: =AVERAGE(C23:C26) -> 0.08 | D7: =AVERAGE(D23:D26) -> 0.08 | E7: =C7-D7 -> 0 | F7: =IF(C7=D7,"Tie",IF(C7>D7,"Tower A","Tower B")) -> Tie
A8: OVERALL | C8: =AVERAGE(C11:C26) -> 0.32328125 | D8: =AVERAGE(D11:D26) -> 0.3125 | E8: =C8-D8 -> 0.01078125 | F8: =IF(C8=D8,"Tie",IF(C8>D8,"Tower A","Tower B")) -> Tower A
A10: PACKAGE | B10: Item | C10: Tower A | D10: Tower B | E10: Gap (A−B) | F10: Leader
A11: Cold Water | B11: Pipe Sleeve | C11: =AVERAGE(PROGRESSION!C6:C25) -> 0.9325 | D11: =AVERAGE(PROGRESSION!C26:C45) -> 0.93 | E11: =C11-D11 -> 0.0025 | F11: =IF(C11=D11,"Tie",IF(C11>D11,"Tower A","Tower B")) -> Tower A
A12: Cold Water | B12: Pump | C12: =AVERAGE(PROGRESSION!D6:D25) -> 0.45 | D12: =AVERAGE(PROGRESSION!D26:D45) -> 0.45 | E12: =C12-D12 -> 0 | F12: =IF(C12=D12,"Tie",IF(C12>D12,"Tower A","Tower B")) -> Tie
A13: Cold Water | B13: Pump Control Panel | C13: =AVERAGE(PROGRESSION!E6:E25) -> 0.45 | D13: =AVERAGE(PROGRESSION!E26:E45) -> 0.45 | E13: =C13-D13 -> 0 | F13: =IF(C13=D13,"Tie",IF(C13>D13,"Tower A","Tower B")) -> Tie
A14: Cold Water | B14: Transfer Pump Pipes | C14: =AVERAGE(PROGRESSION!F6:F25) -> 0.45 | D14: =AVERAGE(PROGRESSION!F26:F45) -> 0.45 | E14: =C14-D14 -> 0 | F14: =IF(C14=D14,"Tie",IF(C14>D14,"Tower A","Tower B")) -> Tie
A15: Cold Water | B15: L31 & 31M Roof Piping | C15: =AVERAGE(PROGRESSION!G6:G25) -> 0 | D15: =AVERAGE(PROGRESSION!G26:G45) -> 0 | E15: =C15-D15 -> 0 | F15: =IF(C15=D15,"Tie",IF(C15>D15,"Tower A","Tower B")) -> Tie
A16: Cold Water | B16: CW Tenant | C16: =AVERAGE(PROGRESSION!H6:H25) -> 0.72 | D16: =AVERAGE(PROGRESSION!H26:H45) -> 0.675 | E16: =C16-D16 -> 0.045 | F16: =IF(C16=D16,"Tie",IF(C16>D16,"Tower A","Tower B")) -> Tower A
A17: Cold Water | B17: Backshaft CW & FW Toilets | C17: =AVERAGE(PROGRESSION!I6:I25) -> 0.105 | D17: =AVERAGE(PROGRESSION!I26:I45) -> 0.105 | E17: =C17-D17 -> 0 | F17: =IF(C17=D17,"Tie",IF(C17>D17,"Tower A","Tower B")) -> Tie
A18: Sanitary | B18: Hosereel Floortrap & Stack | C18: =AVERAGE(PROGRESSION!J6:J25) -> 0.355 | D18: =AVERAGE(PROGRESSION!J26:J45) -> 0.355 | E18: =C18-D18 -> 0 | F18: =IF(C18=D18,"Tie",IF(C18>D18,"Tower A","Tower B")) -> Tie
A19: Sanitary | B19: Sanitary Tenant | C19: =AVERAGE(PROGRESSION!K6:K25) -> 0.325 | D19: =AVERAGE(PROGRESSION!K26:K45) -> 0.325 | E19: =C19-D19 -> 0 | F19: =IF(C19=D19,"Tie",IF(C19>D19,"Tower A","Tower B")) -> Tie
A20: Sanitary | B20: Toilet Pipe Distribution & Hacking | C20: =AVERAGE(PROGRESSION!L6:L25) -> 0.39 | D20: =AVERAGE(PROGRESSION!L26:L45) -> 0.39 | E20: =C20-D20 -> 0 | F20: =IF(C20=D20,"Tie",IF(C20>D20,"Tower A","Tower B")) -> Tie
A21: Sanitary | B21: Sanitary Toilets | C21: =AVERAGE(PROGRESSION!M6:M25) -> 0.55 | D21: =AVERAGE(PROGRESSION!M26:M45) -> 0.45 | E21: =C21-D21 -> 0.1 | F21: =IF(C21=D21,"Tie",IF(C21>D21,"Tower A","Tower B")) -> Tower A
A22: Sanitary | B22: Sanitary Wares Installation | C22: =AVERAGE(PROGRESSION!N6:N25) -> 0.125 | D22: =AVERAGE(PROGRESSION!N26:N45) -> 0.1 | E22: =C22-D22 -> 0.025 | F22: =IF(C22=D22,"Tie",IF(C22>D22,"Tower A","Tower B")) -> Tower A
A23: Irrigation | B23: Irrigation Outlet | C23: =AVERAGE(PROGRESSION!O6:O25) -> 0.275 | D23: =AVERAGE(PROGRESSION!O26:O45) -> 0.275 | E23: =C23-D23 -> 0 | F23: =IF(C23=D23,"Tie",IF(C23>D23,"Tower A","Tower B")) -> Tie
A24: Irrigation | B24: Irrigation Inlet | C24: =AVERAGE(PROGRESSION!P6:P25) -> 0.045 | D24: =AVERAGE(PROGRESSION!P26:P45) -> 0.045 | E24: =C24-D24 -> 0 | F24: =IF(C24=D24,"Tie",IF(C24>D24,"Tower A","Tower B")) -> Tie
A25: Irrigation | B25: Irrigation Wiring | C25: =AVERAGE(PROGRESSION!Q6:Q25) -> 0 | D25: =AVERAGE(PROGRESSION!Q26:Q45) -> 0 | E25: =C25-D25 -> 0 | F25: =IF(C25=D25,"Tie",IF(C25>D25,"Tower A","Tower B")) -> Tie
A26: Irrigation | B26: Irrigation Control Panel | C26: =AVERAGE(PROGRESSION!R6:R25) -> 0 | D26: =AVERAGE(PROGRESSION!R26:R45) -> 0 | E26: =C26-D26 -> 0 | F26: =IF(C26=D26,"Tie",IF(C26>D26,"Tower A","Tower B")) -> Tie

Sheet FLOORS
A1: Floor-by-floor | % complete
A2: ="A ahead "&COUNTIF(E5:E24,"Tower A")&" · B ahead "&COUNTIF(E5:E24,"Tower B")&" · tie "&COUNTIF(E5:E24,"Tie") -> A ahead 6 · B ahead 1 · tie 13
A4: Level | B4: Tower A | C4: Tower B | D4: Gap (A−B) | E4: Leader
A5: =PROGRESSION!A6 -> 13 | B5: =AVERAGE(PROGRESSION!C6:R6) -> 0.325 | C5: =AVERAGE(PROGRESSION!C26:R26) -> 0.33333333 | D5: =B5-C5 -> -0.0083333333 | E5: =IF(B5=C5,"Tie",IF(B5>C5,"Tower A","Tower B")) -> Tower B
A6: =PROGRESSION!A7 -> 14 | B6: =AVERAGE(PROGRESSION!C7:R7) -> 0.825 | C6: =AVERAGE(PROGRESSION!C27:R27) -> 0.825 | D6: =B6-C6 -> 0 | E6: =IF(B6=C6,"Tie",IF(B6>C6,"Tower A","Tower B")) -> Tie
A7: =PROGRESSION!A8 -> 15 | B7: =AVERAGE(PROGRESSION!C8:R8) -> 0.825 | C7: =AVERAGE(PROGRESSION!C28:R28) -> 0.825 | D7: =B7-C7 -> 0 | E7: =IF(B7=C7,"Tie",IF(B7>C7,"Tower A","Tower B")) -> Tie
A8: =PROGRESSION!A9 -> 16 | B8: =AVERAGE(PROGRESSION!C9:R9) -> 0.70833333 | C8: =AVERAGE(PROGRESSION!C29:R29) -> 0.66666667 | D8: =B8-C8 -> 0.041666667 | E8: =IF(B8=C8,"Tie",IF(B8>C8,"Tower A","Tower B")) -> Tower A
A9: =PROGRESSION!A10 -> 17 | B9: =AVERAGE(PROGRESSION!C10:R10) -> 0.65833333 | C9: =AVERAGE(PROGRESSION!C30:R30) -> 0.65833333 | D9: =B9-C9 -> 0 | E9: =IF(B9=C9,"Tie",IF(B9>C9,"Tower A","Tower B")) -> Tie
A10: =PROGRESSION!A11 -> 18 | B10: =AVERAGE(PROGRESSION!C11:R11) -> 0.61666667 | C10: =AVERAGE(PROGRESSION!C31:R31) -> 0.61666667 | D10: =B10-C10 -> 0 | E10: =IF(B10=C10,"Tie",IF(B10>C10,"Tower A","Tower B")) -> Tie
A11: =PROGRESSION!A12 -> 19 | B11: =AVERAGE(PROGRESSION!C12:R12) -> 0.575 | C11: =AVERAGE(PROGRESSION!C32:R32) -> 0.575 | D11: =B11-C11 -> 0 | E11: =IF(B11=C11,"Tie",IF(B11>C11,"Tower A","Tower B")) -> Tie
A12: =PROGRESSION!A13 -> 20 | B12: =AVERAGE(PROGRESSION!C13:R13) -> 0.45 | C12: =AVERAGE(PROGRESSION!C33:R33) -> 0.45 | D12: =B12-C12 -> 0 | E12: =IF(B12=C12,"Tie",IF(B12>C12,"Tower A","Tower B")) -> Tie
A13: =PROGRESSION!A14 -> 21 | B13: =AVERAGE(PROGRESSION!C14:R14) -> 0.33333333 | C13: =AVERAGE(PROGRESSION!C34:R34) -> 0.325 | D13: =B13-C13 -> 0.0083333333 | E13: =IF(B13=C13,"Tie",IF(B13>C13,"Tower A","Tower B")) -> Tower A
A14: =PROGRESSION!A15 -> 22 | B14: =AVERAGE(PROGRESSION!C15:R15) -> 0.3 | C14: =AVERAGE(PROGRESSION!C35:R35) -> 0.3 | D14: =B14-C14 -> 0 | E14: =IF(B14=C14,"Tie",IF(B14>C14,"Tower A","Tower B")) -> Tie
A15: =PROGRESSION!A16 -> 23 | B15: =AVERAGE(PROGRESSION!C16:R16) -> 0.15833333 | C15: =AVERAGE(PROGRESSION!C36:R36) -> 0.15833333 | D15: =B15-C15 -> 0 | E15: =IF(B15=C15,"Tie",IF(B15>C15,"Tower A","Tower B")) -> Tie
A16: =PROGRESSION!A17 -> 24 | B16: =AVERAGE(PROGRESSION!C17:R17) -> 0.15833333 | C16: =AVERAGE(PROGRESSION!C37:R37) -> 0.15833333 | D16: =B16-C16 -> 0 | E16: =IF(B16=C16,"Tie",IF(B16>C16,"Tower A","Tower B")) -> Tie
... A24: =PROGRESSION!A25 -> 31M | B24: =AVERAGE(PROGRESSION!C25:R25) -> 0.00625 | C24: =AVERAGE(PROGRESSION!C45:R45) -> 0.00625 | D24: =B24-C24 -> 0 | E24: =IF(B24=C24,"Tie",IF(B24>C24,"Tower A","Tower B")) -> Tie
A25: OVERALL | B25: =AVERAGE(B5:B24) -> 0.36022917 | C25: =AVERAGE(C5:C24) -> 0.34589583 | D25: =B25-C25 -> 0.014333333 | E25: =IF(B25=C25,"Tie",IF(B25>C25,"Tower A","Tower B")) -> Tower A

Sheet ORDER
A1: Material Order | qty
A2: =PROGRESSION!A3&" · Blue = qty/floor and ordered" -> Report Date: 29 AUGUST 2026 · Blue = qty/floor and ordered
A4: Package | B4: Material | C4: Unit | D4: Qty / floor | E4: Remaining A | F4: Remaining B | G4: Required | H4: Ordered | I4: Balance | J4: Status | K4: Remarks | M4: Package | N4: Required | O4: Ordered | P4: Balance
A5: Cold Water | B5: Pipe sleeve | C5: nos | D5: 1 | E5: {=SUM(IF(ISNUMBER(PROGRESSION!C6:C25),1-PROGRESSION!C6:C25,0))} -> 1.35 | F5: {=SUM(IF(ISNUMBER(PROGRESSION!C26:C45),1-PROGRESSION!C26:C45,0))} -> 1.4 | G5: =D5*(E5+F5) -> 2.75 | H5: 0 | I5: =G5-H5 -> 2.75 | J5: =IF(I5<=0,"Complete",IF(H5>0,"Partial","To Order")) -> To Order | M5: Cold Water | N5: =SUMIF($A$5:$A$23,M5,$G$5:$G$23) -> 81.05 | O5: =SUMIF($A$5:$A$23,M5,$H$5:$H$23) -> 0 | P5: =N5-O5 -> 81.05
A6: Cold Water | B6: Transfer pump pipes | C6: floor | D6: 1 | E6: {=SUM(IF(ISNUMBER(PROGRESSION!F6:F25),1-PROGRESSION!F6:F25,0))} -> 11 | F6: {=SUM(IF(ISNUMBER(PROGRESSION!F26:F45),1-PROGRESSION!F26:F45,0))} -> 11 | G6: =D6*(E6+F6) -> 22 | H6: 0 | I6: =G6-H6 -> 22 | J6: =IF(I6<=0,"Complete",IF(H6>0,"Partial","To Order")) -> To Order | M6: Sanitary | N6: =SUMIF($A$5:$A$23,M6,$G$5:$G$23) -> 582.3 | O6: =SUMIF($A$5:$A$23,M6,$H$5:$H$23) -> 0 | P6: =N6-O6 -> 582.3
A7: Cold Water | B7: CW tenant pipework | C7: floor | D7: 1 | E7: {=SUM(IF(ISNUMBER(PROGRESSION!H6:H25),1-PROGRESSION!H6:H25,0))} -> 5.6 | F7: {=SUM(IF(ISNUMBER(PROGRESSION!H26:H45),1-PROGRESSION!H26:H45,0))} -> 6.5 | G7: =D7*(E7+F7) -> 12.1 | H7: 0 | I7: =G7-H7 -> 12.1 | J7: =IF(I7<=0,"Complete",IF(H7>0,"Partial","To Order")) -> To Order | M7: Irrigation | N7: =SUMIF($A$5:$A$23,M7,$G$5:$G$23) -> 111.2 | O7: =SUMIF($A$5:$A$23,M7,$H$5:$H$23) -> 0 | P7: =N7-O7 -> 111.2
A8: Cold Water | B8: Backshaft CW & FW pipe | C8: floor | D8: 1 | E8: {=SUM(IF(ISNUMBER(PROGRESSION!I6:I25),1-PROGRESSION!I6:I25,0))} -> 17.9 | F8: {=SUM(IF(ISNUMBER(PROGRESSION!I26:I45),1-PROGRESSION!I26:I45,0))} -> 17.9 | G8: =D8*(E8+F8) -> 35.8 | H8: 0 | I8: =G8-H8 -> 35.8 | J8: =IF(I8<=0,"Complete",IF(H8>0,"Partial","To Order")) -> To Order | M8: TOTAL | N8: =SUM(N5:N7) -> 774.55 | O8: =SUM(O5:O7) -> 0 | P8: =SUM(P5:P7) -> 774.55
A9: Cold Water | B9: L31 & 31M roof piping | C9: lot | D9: 1 | E9: {=SUM(IF(ISNUMBER(PROGRESSION!G6:G25),1-PROGRESSION!G6:G25,0))} -> 2 | F9: {=SUM(IF(ISNUMBER(PROGRESSION!G26:G45),1-PROGRESSION!G26:G45,0))} -> 2 | G9: =D9*(E9+F9) -> 4 | H9: 0 | I9: =G9-H9 -> 4 | J9: =IF(I9<=0,"Complete",IF(H9>0,"Partial","To Order")) -> To Order
A10: Cold Water | B10: Pump | C10: set | D10: 1 | E10: {=SUM(IF(ISNUMBER(PROGRESSION!D6:D25),1-PROGRESSION!D6:D25,0))} -> 1.1 | F10: {=SUM(IF(ISNUMBER(PROGRESSION!D26:D45),1-PROGRESSION!D26:D45,0))} -> 1.1 | G10: =D10*(E10+F10) -> 2.2 | H10: 0 | I10: =G10-H10 -> 2.2 | J10: =IF(I10<=0,"Complete",IF(H10>0,"Partial","To Order")) -> To Order
A11: Cold Water | B11: Pump control panel | C11: set | D11: 1 | E11: {=SUM(IF(ISNUMBER(PROGRESSION!E6:E25),1-PROGRESSION!E6:E25,0))} -> 1.1 | F11: {=SUM(IF(ISNUMBER(PROGRESSION!E26:E45),1-PROGRESSION!E26:E45,0))} -> 1.1 | G11: =D11*(E11+F11) -> 2.2 | H11: 0 | I11: =G11-H11 -> 2.2 | J11: =IF(I11<=0,"Complete",IF(H11>0,"Partial","To Order")) -> To Order
A12: Sanitary | B12: Hosereel set | C12: nos | D12: 6 | E12: {=SUM(IF(ISNUMBER(PROGRESSION!J6:J25),1-PROGRESSION!J6:J25,0))} -> 12.9 | F12: {=SUM(IF(ISNUMBER(PROGRESSION!J26:J45),1-PROGRESSION!J26:J45,0))} -> 12.9 | G12: =D12*(E12+F12) -> 154.8 | H12: 0 | I12: =G12-H12 -> 154.8 | J12: =IF(I12<=0,"Complete",IF(H12>0,"Partial","To Order")) -> To Order
A13: Sanitary | B13: Floor trap | C13: nos | D13: 6 | E13: =E12 -> 12.9 | F13: =F12 -> 12.9 | G13: =D13*(E13+F13) -> 154.8 | H13: 0 | I13: =G13-H13 -> 154.8 | J13: =IF(I13<=0,"Complete",IF(H13>0,"Partial","To Order")) -> To Order
A14: Sanitary | B14: Sanitary stack pipe | C14: floor | D14: 1 | E14: =E12 -> 12.9 | F14: =F12 -> 12.9 | G14: =D14*(E14+F14) -> 25.8 | H14: 0 | I14: =G14-H14 -> 25.8 | J14: =IF(I14<=0,"Complete",IF(H14>0,"Partial","To Order")) -> To Order
A15: Sanitary | B15: Toilet distribution pipe | C15: floor | D15: 1 | E15: {=SUM(IF(ISNUMBER(PROGRESSION!L6:L25),1-PROGRESSION!L6:L25,0))} -> 12.2 | F15: {=SUM(IF(ISNUMBER(PROGRESSION!L26:L45),1-PROGRESSION!L26:L45,0))} -> 12.2 | G15: =D15*(E15+F15) -> 24.4 | H15: 0 | I15: =G15-H15 -> 24.4 | J15: =IF(I15<=0,"Complete",IF(H15>0,"Partial","To Order")) -> To Order
A16: Sanitary | B16: Sanitary tenant | C16: floor | D16: 1 | E16: {=SUM(IF(ISNUMBER(PROGRESSION!K6:K25),1-PROGRESSION!K6:K25,0))} -> 13.5 | F16: {=SUM(IF(ISNUMBER(PROGRESSION!K26:K45),1-PROGRESSION!K26:K45,0))} -> 13.5 | G16: =D16*(E16+F16) -> 27 | H16: 0 | I16: =G16-H16 -> 27 | J16: =IF(I16<=0,"Complete",IF(H16>0,"Partial","To Order")) -> To Order
A17: Sanitary | B17: WC pan | C17: nos | D17: 4 | E17: {=SUM(IF(ISNUMBER(PROGRESSION!M6:M25),1-PROGRESSION!M6:M25,0))} -> 9 | F17: {=SUM(IF(ISNUMBER(PROGRESSION!M26:M45),1-PROGRESSION!M26:M45,0))} -> 11 | G17: =D17*(E17+F17) -> 80 | H17: 0 | I17: =G17-H17 -> 80 | J17: =IF(I17<=0,"Complete",IF(H17>0,"Partial","To Order")) -> To Order
A18: Sanitary | B18: Wash basin | C18: nos | D18: 4 | E18: =E17 -> 9 | F18: =F17 -> 11 | G18: =D18*(E18+F18) -> 80 | H18: 0 | I18: =G18-H18 -> 80 | J18: =IF(I18<=0,"Complete",IF(H18>0,"Partial","To Order")) -> To Order
A19: Sanitary | B19: Sanitary wares | C19: floor | D19: 1 | E19: {=SUM(IF(ISNUMBER(PROGRESSION!N6:N25),1-PROGRESSION!N6:N25,0))} -> 17.5 | F19: {=SUM(IF(ISNUMBER(PROGRESSION!N26:N45),1-PROGRESSION!N26:N45,0))} -> 18 | G19: =D19*(E19+F19) -> 35.5 | H19: 0 | I19: =G19-H19 -> 35.5 | J19: =IF(I19<=0,"Complete",IF(H19>0,"Partial","To Order")) -> To Order
A20: Irrigation | B20: Irrigation outlet | C20: nos | D20: 1 | E20: {=SUM(IF(ISNUMBER(PROGRESSION!O6:O25),1-PROGRESSION!O6:O25,0))} -> 14.5 | F20: {=SUM(IF(ISNUMBER(PROGRESSION!O26:O45),1-PROGRESSION!O26:O45,0))} -> 14.5 | G20: =D20*(E20+F20) -> 29 | H20: 0 | I20: =G20-H20 -> 29 | J20: =IF(I20<=0,"Complete",IF(H20>0,"Partial","To Order")) -> To Order
A21: Irrigation | B21: Irrigation inlet | C21: nos | D21: 1 | E21: {=SUM(IF(ISNUMBER(PROGRESSION!P6:P25),1-PROGRESSION!P6:P25,0))} -> 19.1 | F21: {=SUM(IF(ISNUMBER(PROGRESSION!P26:P45),1-PROGRESSION!P26:P45,0))} -> 19.1 | G21: =D21*(E21+F21) -> 38.2 | H21: 0 | I21: =G21-H21 -> 38.2 | J21: =IF(I21<=0,"Complete",IF(H21>0,"Partial","To Order")) -> To Order
A22: Irrigation | B22: Irrigation cable | C22: floor | D22: 1 | E22: {=SUM(IF(ISNUMBER(PROGRESSION!Q6:Q25),1-PROGRESSION!Q6:Q25,0))} -> 20 | F22: {=SUM(IF(ISNUMBER(PROGRESSION!Q26:Q45),1-PROGRESSION!Q26:Q45,0))} -> 20 | G22: =D22*(E22+F22) -> 40 | H22: 0 | I22: =G22-H22 -> 40 | J22: =IF(I22<=0,"Complete",IF(H22>0,"Partial","To Order")) -> To Order
A23: Irrigation | B23: Irrigation control panel | C23: set | D23: 1 | E23: {=SUM(IF(ISNUMBER(PROGRESSION!R6:R25),1-PROGRESSION!R6:R25,0))} -> 2 | F23: {=SUM(IF(ISNUMBER(PROGRESSION!R26:R45),1-PROGRESSION!R26:R45,0))} -> 2 | G23: =D23*(E23+F23) -> 4 | H23: 0 | I23: =G23-H23 -> 4 | J23: =IF(I23<=0,"Complete",IF(H23>0,"Partial","To Order")) -> To Order
A24: TOTAL | E24: =SUM(E5:E23) -> 195.55 | F24: =SUM(F5:F23) -> 201 | G24: =SUM(G5:G23) -> 774.55 | H24: =SUM(H5:H23) -> 0 | I24: =SUM(I5:I23) -> 774.55

Sheet SITE REPORT
A1: Site report | % complete
A2: =PROGRESSION!A3 -> Report Date: 29 AUGUST 2026
A4: Overall | B4: Cold Water | C4: Sanitary | D4: Irrigation | E4: Men | F4: Day RM
A5: =(PROGRESSION!G4+PROGRESSION!L4+PROGRESSION!Q4)/3 -> 0.28567857 | B5: =PROGRESSION!G4 -> 0.44053571 | C5: =PROGRESSION!L4 -> 0.3365 | D5: =PROGRESSION!Q4 -> 0.08 | E5: =COUNTA(Sheet2!C3:C29) -> 27 | F5: =Sheet2!D30 -> 15900
A7: Weather | B7: Fair | C7: Shift | D7: Day
A8: Today | B8: Transfer pump + hosereel
A9: Blockers
A10: Tomorrow
A12: Item | B12: Progress | C12: Status | D12: Owner
A13: =Sheet1!C5 -> PIPE SLEEVE | B13: =Sheet1!E5 -> 0.93125 | C13: =Sheet1!F5 -> In Progress | D13: =Sheet1!D5 -> suhairi
A14: =Sheet1!C6 -> PUMP | B14: =Sheet1!E6 -> 0.45 | C14: =Sheet1!F6 -> In Progress | D14: =Sheet1!D6 -> n/a
A15: =Sheet1!C7 -> PUMP CONTROL PANEL | B15: =Sheet1!E7 -> 0.45 | C15: =Sheet1!F7 -> In Progress | D15: =Sheet1!D7 -> 0
A16: =Sheet1!C8 -> TRANSFER PUMP PIPES | B16: =Sheet1!E8 -> 0.45 | C16: =Sheet1!F8 -> In Progress | D16: =Sheet1!D8 -> subs-aryan
A17: =Sheet1!C9 -> L31 & 31M ROOF PIPING | B17: =Sheet1!E9 -> 0 | C17: =Sheet1!F9 -> Not Started | D17: =Sheet1!D9 -> 0
A18: =Sheet1!C10 -> CW TENANT | B18: =Sheet1!E10 -> 0.6975 | C18: =Sheet1!F10 -> In Progress | D18: =Sheet1!D10 -> asgar
A19: =Sheet1!C11 -> BACKSHAFT CW & FW TOILETS | B19: =Sheet1!E11 -> 0.105 | C19: =Sheet1!F11 -> In Progress | D19: =Sheet1!D11 -> jillur/sarip
A20: =Sheet1!C12 -> HOSEREEL FLOORTRAP & STACK | B20: =Sheet1!E12 -> 0.355 | C20: =Sheet1!F12 -> In Progress | D20: =Sheet1!D12 -> emon
A21: =Sheet1!C13 -> SANITARY TENANT | B21: =Sheet1!E13 -> 0.325 | C21: =Sheet1!F13 -> In Progress | D21: =Sheet1!D13 -> 0
A22: =Sheet1!C14 -> TOILET PIPE DISTRIBUTION & HACKING | B22: =Sheet1!E14 -> 0.39 | C22: =Sheet1!F14 -> In Progress | D22: =Sheet1!D14 -> bilal
A23: =Sheet1!C15 -> SANITARY TOILETS TOWER A | B23: =Sheet1!E15 -> 0.55 | C23: =Sheet1!F15 -> In Progress | D23: =Sheet1!D15 -> subs-aipoon
A24: =Sheet1!C16 -> SANITARY TOILETS TOWER B | B24: =Sheet1!E16 -> 0.45 | C24: =Sheet1!F16 -> In Progress | D24: =Sheet1!D16 -> 0
... A29: =Sheet1!C21 -> IRRIGATION CONTROL PANEL | B29: =Sheet1!E21 -> 0 | C29: =Sheet1!F21 -> Not Started | D29: =Sheet1!D21 -> 0

Sheet PO LOG
A1: PO log | RM
A2: =PROGRESSION!A3 -> Report Date: 29 AUGUST 2026
A4: Date | B4: PO No | C4: Material | D4: Supplier | E4: Qty | F4: Unit | G4: Amount RM | H4: Status | I4: ETA | J4: Remarks | L4: Still to order | M4: Lines
F5: =IF(C5="","",_xlfn.XLOOKUP(C5,ORDER!B$5:B$23,ORDER!C$5:C$23)) | L5: To Order | M5: =COUNTIF(ORDER!J5:J23,"To Order") -> 19
F6: =IF(C6="","",_xlfn.XLOOKUP(C6,ORDER!B$5:B$23,ORDER!C$5:C$23)) | L6: Partial | M6: =COUNTIF(ORDER!J5:J23,"Partial") -> 0
F7: =IF(C7="","",_xlfn.XLOOKUP(C7,ORDER!B$5:B$23,ORDER!C$5:C$23)) | L7: Complete | M7: =COUNTIF(ORDER!J5:J23,"Complete") -> 0
F8: =IF(C8="","",_xlfn.XLOOKUP(C8,ORDER!B$5:B$23,ORDER!C$5:C$23))
F9: =IF(C9="","",_xlfn.XLOOKUP(C9,ORDER!B$5:B$23,ORDER!C$5:C$23))
F10: =IF(C10="","",_xlfn.XLOOKUP(C10,ORDER!B$5:B$23,ORDER!C$5:C$23))
F11: =IF(C11="","",_xlfn.XLOOKUP(C11,ORDER!B$5:B$23,ORDER!C$5:C$23))
F12: =IF(C12="","",_xlfn.XLOOKUP(C12,ORDER!B$5:B$23,ORDER!C$5:C$23))
F13: =IF(C13="","",_xlfn.XLOOKUP(C13,ORDER!B$5:B$23,ORDER!C$5:C$23))
F14: =IF(C14="","",_xlfn.XLOOKUP(C14,ORDER!B$5:B$23,ORDER!C$5:C$23))
F15: =IF(C15="","",_xlfn.XLOOKUP(C15,ORDER!B$5:B$23,ORDER!C$5:C$23))
F16: =IF(C16="","",_xlfn.XLOOKUP(C16,ORDER!B$5:B$23,ORDER!C$5:C$23))
A17: TOTAL | E17: =SUM(E5:E16) -> 0 | G17: =SUM(G5:G16) -> 0 | H17: =COUNTA(H5:H16)&" POs" -> 0 POs

Sheet MANPOWER
A1: Manpower vs progress
A2: =PROGRESSION!A3 -> Report Date: 29 AUGUST 2026
A4: On site | B4: Day RM | C4: Overall | D4: RM / 1% | F4: Package | G4: Progress | H4: Remaining
A5: =SUM(C8:C34) -> 27 | B5: =SUM(D8:D34) -> 15900 | C5: =('SITE REPORT'!A5) -> 0.28567857 | D5: =IF(C5=0,"",B5/(C5*100)) -> 556.56957 | F5: Cold Water | G5: =PROGRESSION!G4 -> 0.44053571 | H5: =1-G5 -> 0.55946429
F6: Sanitary | G6: =PROGRESSION!L4 -> 0.3365 | H6: =1-G6 -> 0.6635
A7: Name | B7: Rate RM | C7: On site | D7: Cost today | F7: Irrigation | G7: =PROGRESSION!Q4 -> 0.08 | H7: =1-G7 -> 0.92
A8: =Sheet2!C3 -> SUPAHAM | B8: =Sheet2!D3 -> 2000 | C8: 1 | D8: =IF(ISNUMBER(B8),B8*C8,0) -> 2000
A9: =Sheet2!C4 -> SOLIHIN | B9: =Sheet2!D4 -> 1000 | C9: 1 | D9: =IF(ISNUMBER(B9),B9*C9,0) -> 1000
A10: =Sheet2!C5 -> ASGAR | B10: =Sheet2!D5 -> 500 | C10: 1 | D10: =IF(ISNUMBER(B10),B10*C10,0) -> 500
A11: =Sheet2!C6 -> SUHAIRI | B11: =Sheet2!D6 -> 700 | C11: 1 | D11: =IF(ISNUMBER(B11),B11*C11,0) -> 700
A12: =Sheet2!C7 -> BILAL | B12: =Sheet2!D7 -> 500 | C12: 1 | D12: =IF(ISNUMBER(B12),B12*C12,0) -> 500
A13: =Sheet2!C8 -> JUWEL | B13: =Sheet2!D8 -> 500 | C13: 1 | D13: =IF(ISNUMBER(B13),B13*C13,0) -> 500
A14: =Sheet2!C9 -> JILLUR | B14: =Sheet2!D9 -> 500 | C14: 1 | D14: =IF(ISNUMBER(B14),B14*C14,0) -> 500
A15: =Sheet2!C10 -> SARIP | B15: =Sheet2!D10 -> 700 | C15: 1 | D15: =IF(ISNUMBER(B15),B15*C15,0) -> 700
A16: =Sheet2!C11 -> EMON | B16: =Sheet2!D11 -> 500 | C16: 1 | D16: =IF(ISNUMBER(B16),B16*C16,0) -> 500
A17: =Sheet2!C12 -> IBNU | B17: =Sheet2!D12 -> 500 | C17: 1 | D17: =IF(ISNUMBER(B17),B17*C17,0) -> 500
A18: =Sheet2!C13 -> KAMAL | B18: =Sheet2!D13 -> 500 | C18: 1 | D18: =IF(ISNUMBER(B18),B18*C18,0) -> 500
A19: =Sheet2!C14 -> YASIN | B19: =Sheet2!D14 -> 500 | C19: 1 | D19: =IF(ISNUMBER(B19),B19*C19,0) -> 500
... A34: =Sheet2!C29 -> KAMAL | B34: =Sheet2!D29 -> 500 | C34: 1 | D34: =IF(ISNUMBER(B34),B34*C34,0) -> 500
A35: TOTAL | C35: =SUM(C8:C34) -> 27 | D35: =SUM(D8:D34) -> 15900

Sheet AIPOON
A1: AIPOON CLAIM
A2: =PROGRESSION!A3 -> Report Date: 29 AUGUST 2026
A3: Subcon | B3: AIPOON | C3: Project | D3: THE CAPITOL / MSK | E3: Claim No | F3: AC-001 | G3: Tower | H3: A/B | I3: Prepared | J3: ALVIN | K3: Verified | L3: KHAIRUL
A4: Toilet RM/point | B4: 50 | C4: Tenant RM/point | D4: 30
A6: TOILET L25-31
A7: Level | B7: Basin | C7: Floor trap | D7: Urinal | E7: Stack | F7: RM/toilet | G7: Toilets | H7: RM/level | I7: Progress | J7: Claimed | K7: Paid | L7: Balance
A8: 24 | B8: 7 | C8: 16 | D8: 3 | E8: 3 | F8: =(B8+C8+D8+E8)*$B$4 -> 1450 | G8: 4 | H8: =F8*G8 -> 5800 | I8: 0.5 | J8: =H8*I8*$H$18/$H$16 -> 2461.5385 | K8: 0 | L8: =J8-K8 -> 2461.5385
A9: 25 | B9: 7 | C9: 16 | D9: 3 | E9: 3 | F9: =(B9+C9+D9+E9)*$B$4 -> 1450 | G9: 4 | H9: =F9*G9 -> 5800 | I9: 0.5 | J9: =H9*I9*$H$18/$H$16 -> 2461.5385 | K9: 0 | L9: =J9-K9 -> 2461.5385
A10: 26 | B10: 7 | C10: 16 | D10: 3 | E10: 3 | F10: =(B10+C10+D10+E10)*$B$4 -> 1450 | G10: 4 | H10: =F10*G10 -> 5800 | I10: =PROGRESSION!M19 -> 0 | J10: =H10*I10*$H$18/$H$16 -> 0 | K10: 0 | L10: =J10-K10 -> 0
A11: 27 | B11: 7 | C11: 16 | D11: 3 | E11: 3 | F11: =(B11+C11+D11+E11)*$B$4 -> 1450 | G11: 4 | H11: =F11*G11 -> 5800 | I11: =PROGRESSION!M20 -> 1 | J11: =H11*I11*$H$18/$H$16 -> 4923.0769 | K11: 0 | L11: =J11-K11 -> 4923.0769
A12: 28 | B12: 7 | C12: 16 | D12: 3 | E12: 3 | F12: =(B12+C12+D12+E12)*$B$4 -> 1450 | G12: 4 | H12: =F12*G12 -> 5800 | I12: =PROGRESSION!M21 -> 0 | J12: =H12*I12*$H$18/$H$16 -> 0 | K12: 0 | L12: =J12-K12 -> 0
A13: 29 | B13: 7 | C13: 16 | D13: 3 | E13: 3 | F13: =(B13+C13+D13+E13)*$B$4 -> 1450 | G13: 4 | H13: =F13*G13 -> 5800 | I13: =PROGRESSION!M22 -> 0 | J13: =H13*I13*$H$18/$H$16 -> 0 | K13: 0 | L13: =J13-K13 -> 0
A14: 30 | B14: 7 | C14: 16 | D14: 3 | E14: 3 | F14: =(B14+C14+D14+E14)*$B$4 -> 1450 | G14: 4 | H14: =F14*G14 -> 5800 | I14: =PROGRESSION!M23 -> 0 | J14: =H14*I14*$H$18/$H$16 -> 0 | K14: 0 | L14: =J14-K14 -> 0
A15: 31 | B15: 7 | C15: 16 | D15: 3 | E15: 3 | F15: =(B15+C15+D15+E15)*$B$4 -> 1450 | G15: 2 | H15: =F15*G15 -> 2900 | I15: =PROGRESSION!M24 -> 0 | J15: =H15*I15*$H$18/$H$16 -> 0 | K15: 0 | L15: =J15-K15 -> 0
A16: Subtotal | H16: =SUM(H9:H15) -> 37700 | J16: =SUM(J9:J15) -> 7384.6154 | K16: =SUM(K9:K15) -> 0 | L16: =J16-K16 -> 7384.6154
A17: Discount | H17: -5700
A18: Toilet final | H18: =H16+H17 -> 32000 | J18: =J16 -> 7384.6154 | K18: =K16 -> 0 | L18: =L16 -> 7384.6154
A20: TENANT L25-31
A21: Level | B21: Floor out | C21: Basin out | D21: Hosereel | E21: Stack | H21: RM/level | I21: Progress | J21: Claimed | K21: Paid | L21: Balance
A22: 25 | B22: 12 | C22: 12 | D22: 12 | E22: 12 | H22: =(B22+C22+D22+E22)*$D$4 -> 1440 | I22: =PROGRESSION!K18 -> 0 | J22: =H22*I22*$H$31/$H$29 -> 0 | K22: 0 | L22: =J22-K22 -> 0
A23: 26 | B23: 12 | C23: 12 | D23: 12 | E23: 12 | H23: =(B23+C23+D23+E23)*$D$4 -> 1440 | I23: =PROGRESSION!K19 -> 0 | J23: =H23*I23*$H$31/$H$29 -> 0 | K23: 0 | L23: =J23-K23 -> 0
A24: 27 | B24: 12 | C24: 12 | D24: 12 | E24: 12 | H24: =(B24+C24+D24+E24)*$D$4 -> 1440 | I24: 1 | J24: =H24*I24*$H$31/$H$29 -> 1428.5714 | K24: 0 | L24: =J24-K24 -> 1428.5714
A25: 28 | B25: 12 | C25: 12 | D25: 12 | E25: 12 | H25: =(B25+C25+D25+E25)*$D$4 -> 1440 | I25: =PROGRESSION!K21 -> 0 | J25: =H25*I25*$H$31/$H$29 -> 0 | K25: 0 | L25: =J25-K25 -> 0
A26: 29 | B26: 12 | C26: 12 | D26: 12 | E26: 12 | H26: =(B26+C26+D26+E26)*$D$4 -> 1440 | I26: =PROGRESSION!K22 -> 0 | J26: =H26*I26*$H$31/$H$29 -> 0 | K26: 0 | L26: =J26-K26 -> 0
A27: 30 | B27: 12 | C27: 12 | D27: 12 | E27: 12 | H27: =(B27+C27+D27+E27)*$D$4 -> 1440 | I27: =PROGRESSION!K23 -> 0 | J27: =H27*I27*$H$31/$H$29 -> 0 | K27: 0 | L27: =J27-K27 -> 0
A28: 31 | B28: 12 | C28: 12 | D28: 12 | E28: 12 | H28: =(B28+C28+D28+E28)*$D$4 -> 1440 | I28: =PROGRESSION!K24 -> 0 | J28: =H28*I28*$H$31/$H$29 -> 0 | K28: 0 | L28: =J28-K28 -> 0
A29: Subtotal | H29: =SUM(H22:H28) -> 10080 | J29: =SUM(J22:J28) -> 1428.5714 | K29: =SUM(K22:K28) -> 0 | L29: =J29-K29 -> 1428.5714
A30: Discount | H30: -80
A31: Tenant final | H31: =H29+H30 -> 10000 | J31: =J29 -> 1428.5714 | K31: =K29 -> 0 | L31: =L29 -> 1428.5714
A33: GRAND TOTAL | H33: =H18+H31 -> 42000 | J33: =J18+J31 -> 8813.1868 | K33: =K18+K31 -> 0 | L33: =J33-K33 -> 8813.1868
A34: Per level | H34: =H33/7 -> 6000
A36: PHOTO LOG
A37: Level | B37: Toilet photo | G37: Tenant photo | K37: Progress | L37: Claimed
A38: 24 | B38: #VALUE! | C38: #VALUE! | D38: Paste photo | E38: Paste photo | G38: Paste photo | H38: Paste photo | I38: Paste photo | J38: Paste photo | K38: 0.5 | L38: 0
A39: 25 | B39: #VALUE! | C39: #VALUE! | D39: Paste photo | E39: Paste photo | G39: Paste photo | H39: Paste photo | I39: Paste photo | J39: Paste photo | K39: 0.5 | L39: =J9 -> 2461.5385
A40: 26 | B40: Paste photo | D40: Paste photo | E40: Paste photo | G40: Paste photo | H40: Paste photo | I40: Paste photo | J40: Paste photo | K40: =I10 -> 0 | L40: =J10 -> 0
A41: 27 | B41: #VALUE! | C41: #VALUE! | D41: #VALUE! | E41: #VALUE! | G41: #VALUE! | H41: #VALUE! | I41: #VALUE! | J41: #VALUE! | K41: =I11 -> 1 | L41: =J11 -> 4923.0769
A42: 28 | B42: Paste photo | C42: Paste photo | D42: Paste photo | E42: Paste photo | G42: Paste photo | H42: Paste photo | I42: Paste photo | J42: Paste photo | K42: =I12 -> 0 | L42: =J12 -> 0
A43: 29 | B43: Paste photo | C43: Paste photo | D43: Paste photo | E43: Paste photo | G43: Paste photo | H43: Paste photo | I43: Paste photo | J43: Paste photo | K43: =I13 -> 0 | L43: =J13 -> 0
A44: 30 | B44: Paste photo | C44: Paste photo | D44: Paste photo | E44: Paste photo | G44: Paste photo | H44: Paste photo | I44: Paste photo | J44: Paste photo | K44: =I14 -> 0 | L44: =J14 -> 0
...

Sheet ARIYAN
A1: ARIYAN | SS pipe | RM
A2: =PROGRESSION!A3 -> Report Date: 29 AUGUST 2026
A3: RM / m | B3: 80 | C3: Fittings extra
A5: TOWER A | I5: TOWER B (L21-31)
A6: Level | B6: Metres | C6: Labour | D6: Fittings | E6: Fit RM | F6: Line | G6: Status | I6: Level | J6: Metres | K6: Labour | L6: Fittings | M6: Fit RM | N6: Line | O6: Status
A7: 13 | B7: 8.6 | C7: =B7*$B$3 -> 688 | D7: 2 ELBOW | E7: 300 | F7: =C7+N(E7) -> 988 | G7: =IF(N(PROGRESSION!F6)>=1,"DONE",IF(N(PROGRESSION!F6)>0,"WIP","")) -> DONE | I7: 21 | J7: 4.5 | K7: =J7*$B$3 -> 360 | M7: 0 | N7: =K7+N(M7) -> 360 | O7: =IF(N(PROGRESSION!F34)>=1,"DONE",IF(N(PROGRESSION!F34)>0,"WIP","")) -> DONE
A8: 14 | B8: 4.5 | C8: =B8*$B$3 -> 360 | D8: 1 ELBOW + 1 CHECK VALVE | E8: 300 | F8: =C8+N(E8) -> 660 | G8: =IF(N(PROGRESSION!F7)>=1,"DONE",IF(N(PROGRESSION!F7)>0,"WIP","")) -> DONE | I8: 22 | J8: 4.5 | K8: =J8*$B$3 -> 360 | M8: 0 | N8: =K8+N(M8) -> 360 | O8: =IF(N(PROGRESSION!F35)>=1,"DONE",IF(N(PROGRESSION!F35)>0,"WIP",""))
A9: 15 | B9: 4.5 | C9: =B9*$B$3 -> 360 | E9: 0 | F9: =C9+N(E9) -> 360 | G9: =IF(N(PROGRESSION!F8)>=1,"DONE",IF(N(PROGRESSION!F8)>0,"WIP","")) -> DONE | I9: 23 | J9: 4.5 | K9: =J9*$B$3 -> 360 | M9: 0 | N9: =K9+N(M9) -> 360 | O9: =IF(N(PROGRESSION!F36)>=1,"DONE",IF(N(PROGRESSION!F36)>0,"WIP",""))
A10: 16 | B10: 4.5 | C10: =B10*$B$3 -> 360 | E10: 0 | F10: =C10+N(E10) -> 360 | G10: =IF(N(PROGRESSION!F9)>=1,"DONE",IF(N(PROGRESSION!F9)>0,"WIP","")) -> DONE | I10: 24 | J10: 4.5 | K10: =J10*$B$3 -> 360 | M10: 0 | N10: =K10+N(M10) -> 360 | O10: =IF(N(PROGRESSION!F37)>=1,"DONE",IF(N(PROGRESSION!F37)>0,"WIP",""))
A11: 17 | B11: 4.5 | C11: =B11*$B$3 -> 360 | E11: 0 | F11: =C11+N(E11) -> 360 | G11: =IF(N(PROGRESSION!F10)>=1,"DONE",IF(N(PROGRESSION!F10)>0,"WIP","")) -> DONE | I11: 25 | J11: 4.5 | K11: =J11*$B$3 -> 360 | M11: 0 | N11: =K11+N(M11) -> 360 | O11: =IF(N(PROGRESSION!F38)>=1,"DONE",IF(N(PROGRESSION!F38)>0,"WIP",""))
A12: 18 | B12: 4.5 | C12: =B12*$B$3 -> 360 | E12: 0 | F12: =C12+N(E12) -> 360 | G12: =IF(N(PROGRESSION!F11)>=1,"DONE",IF(N(PROGRESSION!F11)>0,"WIP","")) -> DONE | I12: 26 | J12: 4.5 | K12: =J12*$B$3 -> 360 | M12: 0 | N12: =K12+N(M12) -> 360 | O12: =IF(N(PROGRESSION!F39)>=1,"DONE",IF(N(PROGRESSION!F39)>0,"WIP",""))
A13: 19 | B13: 4.5 | C13: =B13*$B$3 -> 360 | E13: 0 | F13: =C13+N(E13) -> 360 | G13: =IF(N(PROGRESSION!F12)>=1,"DONE",IF(N(PROGRESSION!F12)>0,"WIP","")) -> DONE | I13: 27 | J13: 5.1 | K13: =J13*$B$3 -> 408 | M13: 0 | N13: =K13+N(M13) -> 408 | O13: =IF(N(PROGRESSION!F40)>=1,"DONE",IF(N(PROGRESSION!F40)>0,"WIP",""))
A14: 20 | B14: 4.5 | C14: =B14*$B$3 -> 360 | E14: 0 | F14: =C14+N(E14) -> 360 | G14: =IF(N(PROGRESSION!F13)>=1,"DONE",IF(N(PROGRESSION!F13)>0,"WIP","")) -> DONE | I14: 28 | J14: 5.1 | K14: =J14*$B$3 -> 408 | M14: 0 | N14: =K14+N(M14) -> 408 | O14: =IF(N(PROGRESSION!F41)>=1,"DONE",IF(N(PROGRESSION!F41)>0,"WIP",""))
A15: 21 | B15: 4.5 | C15: =B15*$B$3 -> 360 | E15: 0 | F15: =C15+N(E15) -> 360 | G15: =IF(N(PROGRESSION!F14)>=1,"DONE",IF(N(PROGRESSION!F14)>0,"WIP","")) -> DONE | I15: 29 | J15: 5.1 | K15: =J15*$B$3 -> 408 | M15: 0 | N15: =K15+N(M15) -> 408 | O15: =IF(N(PROGRESSION!F42)>=1,"DONE",IF(N(PROGRESSION!F42)>0,"WIP",""))
A16: 22 | B16: 4.5 | C16: =B16*$B$3 -> 360 | E16: 0 | F16: =C16+N(E16) -> 360 | G16: =IF(N(PROGRESSION!F15)>=1,"DONE",IF(N(PROGRESSION!F15)>0,"WIP","")) | I16: 30 | J16: 6 | K16: =J16*$B$3 -> 480 | M16: 0 | N16: =K16+N(M16) -> 480 | O16: =IF(N(PROGRESSION!F43)>=1,"DONE",IF(N(PROGRESSION!F43)>0,"WIP",""))
A17: 23 | B17: 4.5 | C17: =B17*$B$3 -> 360 | E17: 0 | F17: =C17+N(E17) -> 360 | G17: =IF(N(PROGRESSION!F16)>=1,"DONE",IF(N(PROGRESSION!F16)>0,"WIP","")) | I17: 31 | J17: 4.9 | K17: =J17*$B$3 -> 392 | M17: 0 | N17: =K17+N(M17) -> 392 | O17: =IF(N(PROGRESSION!F44)>=1,"DONE",IF(N(PROGRESSION!F44)>0,"WIP",""))
A18: 24 | B18: 4.5 | C18: =B18*$B$3 -> 360 | E18: 0 | F18: =C18+N(E18) -> 360 | G18: =IF(N(PROGRESSION!F17)>=1,"DONE",IF(N(PROGRESSION!F17)>0,"WIP","")) | I18: TOTAL | K18: =SUM(K7:K17) -> 4256 | M18: =SUM(M7:M17) -> 0 | N18: =SUM(N7:N17) -> 4256
A19: 25 | B19: 4.5 | C19: =B19*$B$3 -> 360 | E19: 0 | F19: =C19+N(E19) -> 360 | G19: =IF(N(PROGRESSION!F18)>=1,"DONE",IF(N(PROGRESSION!F18)>0,"WIP","")) | I19: Certified DONE | N19: =SUMIF(O7:O17,"DONE",N7:N17) -> 360
A20: 26 | B20: 4.5 | C20: =B20*$B$3 -> 360 | E20: 0 | F20: =C20+N(E20) -> 360 | G20: =IF(N(PROGRESSION!F19)>=1,"DONE",IF(N(PROGRESSION!F19)>0,"WIP",""))
A21: 27 | B21: 5.1 | C21: =B21*$B$3 -> 408 | E21: 0 | F21: =C21+N(E21) -> 408 | G21: =IF(N(PROGRESSION!F20)>=1,"DONE",IF(N(PROGRESSION!F20)>0,"WIP",""))
A22: 28 | B22: 5.1 | C22: =B22*$B$3 -> 408 | E22: 0 | F22: =C22+N(E22) -> 408 | G22: =IF(N(PROGRESSION!F21)>=1,"DONE",IF(N(PROGRESSION!F21)>0,"WIP",""))
A23: 29 | B23: 5.1 | C23: =B23*$B$3 -> 408 | E23: 0 | F23: =C23+N(E23) -> 408 | G23: =IF(N(PROGRESSION!F22)>=1,"DONE",IF(N(PROGRESSION!F22)>0,"WIP",""))
A24: 30 | B24: 6 | C24: =B24*$B$3 -> 480 | E24: 0 | F24: =C24+N(E24) -> 480 | G24: =IF(N(PROGRESSION!F23)>=1,"DONE",IF(N(PROGRESSION!F23)>0,"WIP",""))
A25: 31 | B25: 4.9 | C25: =B25*$B$3 -> 392 | E25: 0 | F25: =C25+N(E25) -> 392 | G25: =IF(N(PROGRESSION!F24)>=1,"DONE",IF(N(PROGRESSION!F24)>0,"WIP",""))
A26: TOTAL | C26: =SUM(C7:C25) -> 7464 | E26: =SUM(E7:E25) -> 600 | F26: =SUM(F7:F25) -> 8064
A27: Certified DONE | F27: =SUMIF(G7:G25,"DONE",F7:F25) -> 4168
